Workbook

Sheet Overview
B2: Eurodrone sizing model
B4: Edit yellow cells on Inputs and Mission. Results and charts recalculate. Start with masses, battery, drag area and efficiencies.
B5: ESTIMATE: illustrative multirotor assumptions. Required performance is calculated; available propulsion capability needs test data.
B7: At target: steady level | C7: Estimate | D7: Unit
B8: All-up mass | C8: =Inputs!C55 -> 1.16625 | D8: kg
B9: Airframe drag | C9: =Model!H9 -> 27.222222 | D9: N
B10: Total thrust required | C10: =Model!K9 -> 29.527182 | D10: N
B11: Thrust required per rotor | C11: =Model!K9/Inputs!C25 -> 7.3817955 | D11: N
B12: Required tilt from vertical | C12: =Model!L9 -> 67.211024 | D12: degrees
B13: Electrical power required | C13: =Model!T9 -> 4035.5772 | D13: W
B14: Hover electrical power | C14: =Model!T8 -> 205.65101 | D14: W
B15: Target airspeed | C15: =Model!C9 -> 300 | D15: km/h
B16: TLR-01 target comparison | C16: =IF(C15<300,"Target below 300 km/h","Target at least 300 km/h") -> Target at least 300 km/h
B19: Flight energy budget | C19: Estimate | D19: Unit
B20: Nominal battery energy | C20: =Inputs!C53 -> 66.6 | D20: Wh
B21: Usable battery energy | C21: =Inputs!C59 -> 53.28 | D21: Wh
B22: Reserved for recovery | C22: =Inputs!C60 -> 10.656 | D22: Wh
B23: Available for nominal mission | C23: =Inputs!C61 -> 42.624 | D23: Wh
B24: Nominal mission energy | C24: =Mission!J16 -> 19.426648 | D24: Wh
B25: Remaining after mission + reserve | C25: =C23-C24 -> 23.197352 | D25: Wh
B26: Powered time | C26: =Mission!C16 -> 120 | D26: seconds
B27: Airborne time | C27: =Mission!C17 -> 90 | D27: seconds
B28: Peak sampled electrical power | C28: =Mission!K16 -> 5517.5612 | D28: W
B29: Peak sampled pack current | C29: =Mission!C19 -> 262.74101 | D29: A
B31: Mission energy assessment | C31: =IF(C25>=0,"Within assumed budget","Exceeds assumed budget") -> Within assumed budget
B34: Energy reserve and hold duration remain sizing assumptions.
B35: Positive energy margin does not establish flight feasibility.
B38: Capability comparison | C38: Headroom | D38: Unit | F38: Interpretation
B39: Hover thrust headroom | C39: =IF(Inputs!C47="","n.a.",IF(Inputs!E47="Entered",Inputs!C47*Inputs!C25/Model!K8-1,NA())) -> n.a. | D39: % | F39: Available / required − 1. Static thrust applies only to hover.
B40: Target-speed thrust headroom | C40: =IF(Inputs!C48="","n.a.",IF(Inputs!E48="Entered",Inputs!C48*Inputs!C25/Model!K9-1,NA())) -> n.a. | D40: % | F40: Requires thrust data at target airspeed and inflow angle.
B41: Pack current headroom | C41: =IF(Inputs!C44="","n.a.",IF(Inputs!E44="Entered",Inputs!C44-Mission!C19,NA())) -> n.a. | D41: A | F41: Limit minus peak sampled demand. No short-duration current spikes modeled.
B42: ESC current headroom / rotor | C42: =IF(Inputs!C45="","n.a.",IF(Inputs!E45="Entered",Inputs!C45-Mission!I19/Inputs!C62,NA())) -> n.a. | D42: A | F42: Equal rotor loading assumed. Real control corrections may load one rotor more.
B43: Power headroom / rotor | C43: =IF(Inputs!C46="","n.a.",IF(Inputs!E46="Entered",Inputs!C46-Mission!I19,NA())) -> n.a. | D43: W | F43: Limit minus peak sampled electrical propulsion power per rotor.
B45: n.a. means no capability input. Enter supported limits in Inputs C44:C48. Negative headroom indicates an exceeded entered limit.
B46: Thrust headroom is not a demonstrated attitude-control margin. No maximum attainable speed is inferred from static thrust.
B48: MODEL LIMITS THAT MATTER
B49: Aerodynamics: fixed drag area across attitude; ideal rotor inflow with constant loss efficiencies. No blade pitch, RPM or tip-speed limit.
B50: Mission: takeoff/landing are hover proxies; braking uses steady-power samples with no regeneration. Peaks are sampled, not electrical transients.
B51: Battery: mass scales with nominal energy. Usable energy and loaded voltage are inputs; temperature, voltage drop and cutoff must be measured.
B52: Next evidence: component masses, drag at flight attitude, propulsion maps and loaded battery tests. Bench checks precede incremental flight tests.

Sheet Inputs
B2: Aircraft inputs
B4: Yellow cells are editable. All populated design values are ASSUMPTION examples, not selected or measured hardware.
B5: Replace component masses first. Battery mass changes automatically with capacity and pack energy density.
B7: Component | C7: Quantity | D7: Each (g) | E7: Total (g) | G7: Input guidance
B8: Primary structure | C8: 1 | D8: 200 | E8: =IF(AND(COUNT(C8:D8)=2,C8>=0,MOD(C8,1)=0,D8>=0),C8*D8,NA()) -> 200 | G8: Custom structure allowance (TLR-02). No strength or stiffness analysis.
B9: Motors | C9: =$C$25 -> 4 | D9: 55 | E9: =IF(AND(COUNT(C9:D9)=2,C9>=0,MOD(C9,1)=0,D9>=0),C9*D9,NA()) -> 220 | G9: Quantity follows rotor count. Replace with selected motor mass.
B10: Motor controllers (ESCs) | C10: =$C$25 -> 4 | D10: 15 | E10: =IF(AND(COUNT(C10:D10)=2,C10>=0,MOD(C10,1)=0,D10>=0),C10*D10,NA()) -> 60 | G10: Mass per motor channel. Use a share of a combined ESC board if applicable.
B11: Propellers | C11: =$C$25 -> 4 | D11: 5 | E11: =IF(AND(COUNT(C11:D11)=2,C11>=0,MOD(C11,1)=0,D11>=0),C11*D11,NA()) -> 20 | G11: Quantity follows rotor count. Equal, non-overlapping rotors assumed.
B12: Flight controller + FPGA | C12: 1 | D12: 55 | E12: =IF(AND(COUNT(C12:D12)=2,C12>=0,MOD(C12,1)=0,D12>=0),C12*D12,NA()) -> 55 | G12: Includes FPGA provision required by TLR-06.
B13: Power distribution | C13: 1 | D13: 25 | E13: =IF(AND(COUNT(C13:D13)=2,C13>=0,MOD(C13,1)=0,D13>=0),C13*D13,NA()) -> 25 | G13: Custom PDU allowance (TLR-02).
B14: Wiring + connectors | C14: 1 | D14: 45 | E14: =IF(AND(COUNT(C14:D14)=2,C14>=0,MOD(C14,1)=0,D14>=0),C14*D14,NA()) -> 45 | G14: Custom harness allowance (TLR-02).
B15: FPV camera + video system | C15: 1 | D15: 40 | E15: =IF(AND(COUNT(C15:D15)=2,C15>=0,MOD(C15,1)=0,D15>=0),C15*D15,NA()) -> 40 | G15: Camera, video transmitter and its antennas (TLR-07).
B16: Pilot receiver + antennas | C16: 1 | D16: 20 | E16: =IF(AND(COUNT(C16:D16)=2,C16>=0,MOD(C16,1)=0,D16>=0),C16*D16,NA()) -> 20 | G16: Pilot link equipment (TLR-07).
B17: Mounts + fasteners | C17: 1 | D17: 35 | E17: =IF(AND(COUNT(C17:D17)=2,C17>=0,MOD(C17,1)=0,D17>=0),C17*D17,NA()) -> 35 | G17: Include battery restraint and electronics mounts.
B18: Other equipment | C18: 1 | D18: 0 | E18: =IF(AND(COUNT(C18:D18)=2,C18>=0,MOD(C18,1)=0,D18>=0),C18*D18,NA()) -> 0 | G18: Optional equipment. Zero is an intentional empty allowance.
B19: Unallocated mass | C19: 1 | D19: 30 | E19: =IF(AND(COUNT(C19:D19)=2,C19>=0,MOD(C19,1)=0,D19>=0),C19*D19,NA()) -> 30 | G19: Editable growth allowance. No prescribed design margin.
B20: Battery pack | C20: 1 | D20: =C54*1000 -> 416.25 | E20: =C20*D20 -> 416.25 | G20: Calculated from nominal Wh / pack energy density. Include pack leads in energy density.
B21: TOTAL MASS | E21: =SUM(E8:E20) -> 1166.25
B24: AIRCRAFT AND ENVIRONMENT
B25: Rotor count | C25: 4 | D25: rotors | E25: =IF(AND(ISNUMBER(C25),C25>=1,C25<=16),IF(MOD(C25,1)=0,"OK","Check input"),"Check input") -> OK | G25: Equal rotors, coplanar and non-overlapping. Mass quantities above follow this value.
B26: Propeller diameter | C26: 5 | D26: in | E26: =IF(AND(ISNUMBER(C26),C26>=0.1,C26<=100),"OK","Check input") -> OK | G26: Affects ideal disk loading. Update propeller/motor masses separately after a size change.
B27: Air density | C27: 1.225 | D27: kg/m³ | E27: =IF(AND(ISNUMBER(C27),C27>=0.1,C27<=2),"OK","Check input") -> OK | G27: ASSUMPTION: representative sea-level density. Enter local conditions when known.
B28: Drag coefficient, Cd | C28: 0.8 | D28: dimensionless | E28: =IF(AND(ISNUMBER(C28),C28>=0,C28<=10),"OK","Check input") -> OK | G28: ASSUMPTION: placeholder. Use Cd consistent with the reference area below.
B29: Projected reference area | C29: 0.008 | D29: m² | E29: =IF(AND(ISNUMBER(C29),C29>=0,C29<=10),"OK","Check input") -> OK | G29: 0.008 m² = 80 cm². Area at flight attitude; CdA is held constant across speeds.
B30: Rotor aerodynamic efficiency | C30: 0.65 | D30: fraction | E30: =IF(AND(ISNUMBER(C30),C30>=0.01,C30<=1),"OK","Check input") -> OK | G30: Ideal disk power / shaft power. Effective loss allowance, not conventional propulsive efficiency.
B31: Motor + ESC efficiency | C31: 0.9 | D31: fraction | E31: =IF(AND(ISNUMBER(C31),C31>=0.01,C31<=1),"OK","Check input") -> OK | G31: Shaft power / electrical propulsion power. Constant assumed value across the profile.
B32: Electronics power | C32: 18 | D32: W | E32: =IF(AND(ISNUMBER(C32),C32>=0,C32<=10000),"OK","Check input") -> OK | G32: Battery-side demand for FC, FPGA, camera, radios and regulators. Present during startup too.
B33: Target airspeed | C33: 300 | D33: km/h | E33: =IF(AND(ISNUMBER(C33),C33>=0,C33<=1000),"OK","Check input") -> OK | G33: TLR-01 design objective: at least 300 km/h. Editing this does not change the requirement.
B34: Speed-chart range / target | C34: 1.2 | D34: multiple | E34: =IF(AND(ISNUMBER(C34),C34>=0.1,C34<=5),"OK","Check input") -> OK | G34: Chart sweeps from hover to this multiple of target speed. Demand only, not attainable speed.
B36: BATTERY
B37: Battery cells in series | C37: 6 | D37: cells | E37: =IF(AND(ISNUMBER(C37),C37>=1,C37<=100),IF(MOD(C37,1)=0,"OK","Check input"),"Check input") -> OK | G37: Equal cells. Capacity below is total pack capacity, including any parallel strings.
B38: Nominal cell voltage | C38: 3.7 | D38: V | E38: =IF(AND(ISNUMBER(C38),C38>=0.1,C38<=10),"OK","Check input") -> OK | G38: Used to calculate stored nominal energy.
B39: Pack capacity | C39: 3000 | D39: mAh | E39: =IF(AND(ISNUMBER(C39),C39>=1,C39<=1000000),"OK","Check input") -> OK | G39: Changing capacity also changes calculated battery mass at fixed pack energy density.
B40: Pack energy density | C40: 160 | D40: Wh/kg | E40: =IF(AND(ISNUMBER(C40),C40>=1,C40<=1000),"OK","Check input") -> OK | G40: Nominal Wh divided by complete pack mass. ASSUMPTION example; replace with pack data.
B41: Usable energy fraction | C41: 0.8 | D41: fraction | E41: =IF(AND(ISNUMBER(C41),C41>=0.01,C41<=1),"OK","Check input") -> OK | G41: Share of nominal Wh usable under the intended load. Capacity, voltage drop and cutoff allowance.
B42: Recovery reserve / usable energy | C42: 0.2 | D42: fraction | E42: =IF(AND(ISNUMBER(C42),C42>=0,C42<=0.99),"OK","Check input") -> OK | G42: ASSUMPTION, not an acceptance limit. Held back from the nominal mission budget.
B43: Operating cell voltage | C43: 3.5 | D43: V | E43: =IF(AND(ISNUMBER(C43),C43>=0.1,C43<=10),"OK","Check input") -> OK | G43: Loaded voltage used for current estimates. Constant; no time-dependent voltage-drop model.
B44: Pack current limit | D44: A | E44: =IF(C44="","No data",IF(AND(ISNUMBER(C44),C44>=0,C44<=1000000000),"Entered","Check input")) -> No data | G44: Optional: supported battery/harness current for this duty. Leave blank without data.
B45: ESC current limit per rotor | D45: A | E45: =IF(C45="","No data",IF(AND(ISNUMBER(C45),C45>=0,C45<=1000000000),"Entered","Check input")) -> No data | G45: Optional: battery-side current per ESC for this duty; not motor phase current.
B46: Electrical power limit per rotor | D46: W | E46: =IF(C46="","No data",IF(AND(ISNUMBER(C46),C46>=0,C46<=1000000000),"Entered","Check input")) -> No data | G46: Optional: motor/ESC electrical input capability for this duty.
...

Sheet Mission
B2: Flight energy budget
B4: Edit yellow durations, end-speed fractions and support loads. 100% speed means the target set on Inputs.
B5: ESTIMATE: default durations from MP-01. Acceleration uses three-point Simpson integration. Braking uses a steady-flight proxy.
B7: Phase | C7: Time (s) | D7: End speed / target | E7: Support load (× weight) | F7: Start (km/h) | G7: End (km/h) | H7: Positive accel. (m/s²) | I7: Mean input power (W) | J7: Energy (Wh) | K7: Peak sampled power (W) | M7: Phase assumption
B8: Startup / readiness | C8: 30 | D8: =0 -> 0 | E8: =1 -> 1 | F8: =0 -> 0 | G8: =IF(AND(AND(ISNUMBER(D8),D8>=0,D8<=3),Inputs!E33="OK"),D8*Inputs!C33,NA()) -> 0 | H8: =IF(AND(AND(ISNUMBER(C8),C8>=0,C8<=100000),AND(ISNUMBER(E8),E8>=1,E8<=10)),IF(C8=0,IF(F8=G8,0,NA()),MAX(0,(G8-F8)/3.6/C8)),NA()) -> 0 | I8: =(Model!T36+4*Model!T37+Model!T38)/6 -> 18 | J8: =I8*C8/3600 -> 0.15 | K8: =IF(C8=0,0,MAX(Model!T36:T38)) -> 18 | M8: Rotors off. Electronics draw only.
B9: Takeoff / hover / alignment | C9: 15 | D9: 0 | E9: 1.1 | F9: =G8 -> 0 | G9: =IF(AND(AND(ISNUMBER(D9),D9>=0,D9<=3),Inputs!E33="OK"),D9*Inputs!C33,NA()) -> 0 | H9: =IF(AND(AND(ISNUMBER(C9),C9>=0,C9<=100000),AND(ISNUMBER(E9),E9>=1,E9<=10)),IF(C9=0,IF(F9=G9,0,NA()),MAX(0,(G9-F9)/3.6/C9)),NA()) -> 0 | I9: =(Model!T39+4*Model!T40+Model!T41)/6 -> 234.49104 | J9: =I9*C9/3600 -> 0.97704602 | K9: =IF(C9=0,0,MAX(Model!T39:T41)) -> 234.49104 | M9: Hover proxy with 10% extra support load; vertical climb is not resolved.
B10: Acceleration | C10: 10 | D10: 1 | E10: 1 | F10: =G9 -> 0 | G10: =IF(AND(AND(ISNUMBER(D10),D10>=0,D10<=3),Inputs!E33="OK"),D10*Inputs!C33,NA()) -> 300 | H10: =IF(AND(AND(ISNUMBER(C10),C10>=0,C10<=100000),AND(ISNUMBER(E10),E10>=1,E10<=10)),IF(C10=0,IF(F10=G10,0,NA()),MAX(0,(G10-F10)/3.6/C10)),NA()) -> 8.3333333 | I10: =(Model!T42+4*Model!T43+Model!T44)/6 -> 1849.1904 | J10: =I10*C10/3600 -> 5.1366401 | K10: =IF(C10=0,0,MAX(Model!T42:T44)) -> 5517.5612 | M10: Linear speed ramp; positive acceleration adds force and kinetic-energy demand.
B11: High-speed level pass | C11: 5 | D11: 1 | E11: 1 | F11: =G10 -> 300 | G11: =IF(AND(AND(ISNUMBER(D11),D11>=0,D11<=3),Inputs!E33="OK"),D11*Inputs!C33,NA()) -> 300 | H11: =IF(AND(AND(ISNUMBER(C11),C11>=0,C11<=100000),AND(ISNUMBER(E11),E11>=1,E11<=10)),IF(C11=0,IF(F11=G11,0,NA()),MAX(0,(G11-F11)/3.6/C11)),NA()) -> 0 | I11: =(Model!T45+4*Model!T46+Model!T47)/6 -> 4035.5772 | J11: =I11*C11/3600 -> 5.6049684 | K11: =IF(C11=0,0,MAX(Model!T45:T47)) -> 4035.5772 | M11: Five seconds is a sizing estimate, not a settled qualifying hold duration.
B12: Deceleration / turn | C12: 15 | D12: 0.2 | E12: 1.2 | F12: =G11 -> 300 | G12: =IF(AND(AND(ISNUMBER(D12),D12>=0,D12<=3),Inputs!E33="OK"),D12*Inputs!C33,NA()) -> 60 | H12: =IF(AND(AND(ISNUMBER(C12),C12>=0,C12<=100000),AND(ISNUMBER(E12),E12>=1,E12<=10)),IF(C12=0,IF(F12=G12,0,NA()),MAX(0,(G12-F12)/3.6/C12)),NA()) -> 0 | I12: =(Model!T48+4*Model!T49+Model!T50)/6 -> 1327.2368 | J12: =I12*C12/3600 -> 5.5301531 | K12: =IF(C12=0,0,MAX(Model!T48:T50)) -> 4044.7988 | M12: Steady-power proxy along speed ramp; 20% extra support load; no regeneration.
B13: Return | C13: 35 | D13: 0.2 | E13: 1 | F13: =G12 -> 60 | G13: =IF(AND(AND(ISNUMBER(D13),D13>=0,D13<=3),Inputs!E33="OK"),D13*Inputs!C33,NA()) -> 60 | H13: =IF(AND(AND(ISNUMBER(C13),C13>=0,C13<=100000),AND(ISNUMBER(E13),E13>=1,E13<=10)),IF(C13=0,IF(F13=G13,0,NA()),MAX(0,(G13-F13)/3.6/C13)),NA()) -> 0 | I13: =(Model!T51+4*Model!T52+Model!T53)/6 -> 150.49489 | J13: =I13*C13/3600 -> 1.4631447 | K13: =IF(C13=0,0,MAX(Model!T51:T53)) -> 150.49489 | M13: Return speed defaults to 20% of target. Course distance and wind are not modeled.
B14: Landing | C14: 10 | D14: 0 | E14: 1.1 | F14: =G13 -> 60 | G14: =IF(AND(AND(ISNUMBER(D14),D14>=0,D14<=3),Inputs!E33="OK"),D14*Inputs!C33,NA()) -> 0 | H14: =IF(AND(AND(ISNUMBER(C14),C14>=0,C14<=100000),AND(ISNUMBER(E14),E14>=1,E14<=10)),IF(C14=0,IF(F14=G14,0,NA()),MAX(0,(G14-F14)/3.6/C14)),NA()) -> 0 | I14: =(Model!T54+4*Model!T55+Model!T56)/6 -> 203.29054 | J14: =I14*C14/3600 -> 0.56469595 | K14: =IF(C14=0,0,MAX(Model!T54:T56)) -> 234.49104 | M14: Steady-power proxy down to hover; vertical descent dynamics are not resolved.
B16: TOTAL POWERED TIME | C16: =SUM(C8:C14) -> 120 | I16: Total energy | J16: =SUM(J8:J14) -> 19.426648 | K16: =MAX(K8:K14) -> 5517.5612
B17: AIRBORNE TIME | C17: =SUM(C9:C14) -> 90
B19: Peak sampled pack current | C19: =K16/Inputs!C62 -> 262.74101 | D19: A | F19: Peak propulsion / rotor | I19: =(K16-Inputs!C32)/Inputs!C25 -> 1374.8903 | J19: W/rotor
B22: HOW THE BUDGET WORKS
B23: Each airborne phase is evaluated at its start, midpoint and end speed. Energy = (Pstart + 4 × Pmid + Pend) / 6 × time / 3600.
B24: Positive acceleration is derived from speed change / duration. It increases horizontal thrust and power. Deceleration is modeled at zero acceleration.
B25: This braking proxy deliberately gives no energy-recovery credit. It does not calculate reverse tilt, vortex-ring state or actual braking loads.
B26: Support load is a coarse allowance for lift demand in maneuvers. It is not a turn-radius, vertical-trajectory or attitude-control model.
B27: Peak sampled power is the maximum of the evaluated points, not a transient electrical peak. Startup assumes rotors are stopped.
B28: Set a phase duration to zero only if start and end speeds are equal. A speed jump in zero time makes results unavailable.
B29: ASSUMPTION: speed is airspeed in still air. No route length, wind, climb height, thermal transient or state-of-charge integration is included.
B30: MP-01 source: requirements/DERIVED_REQUIREMENTS.md. Default duration sequence: 30, 15, 10, 5, 15, 35, 10 seconds.
B31: Recovery reserve is separate on Inputs and is deducted from the usable energy before comparing this nominal mission.

Sheet Model
B2: Physics calculations
B4: ESTIMATE: one formula model for hover, target, speed sweep and mission samples. Inputs are linked; edit the yellow cells on Inputs or Mission.
B5: Required demand only. The X:AU columns solve ideal inflow without circular references. W is relative momentum-equation residual.
B7: Operating point | C7: Speed (km/h) | D7: Positive accel. (m/s²) | E7: Support load | F7: Rotors on | G7: Speed (m/s) | H7: Drag (N) | I7: Forward force (N) | J7: Support force (N) | K7: Total thrust (N) | L7: Tilt (deg) | M7: Axial inflow (m/s) | N7: In-plane flow (m/s) | O7: Hover inflow (m/s) | P7: Solved inflow (m/s) | Q7: Ideal induced power (W) | R7: Translation power (W) | S7: Shaft power (W) | T7: Electrical power (W) | U7: Pack current (A) | V7: Propulsion per rotor (W) | W7: Solver residual | X7: Inflow step 1 | Y7: Inflow step 2 | Z7: Inflow step 3 | AA7: Inflow step 4 | AB7: Inflow step 5 | AC7: Inflow step 6 | AD7: Inflow step 7 | AE7: Inflow step 8 | AF7: Inflow step 9 | AG7: Inflow step 10 | AH7: Inflow step 11 | AI7: Inflow step 12 | AJ7: Inflow step 13 | AK7: Inflow step 14 | AL7: Inflow step 15 | AM7: Inflow step 16 | AN7: Inflow step 17 | AO7: Inflow step 18 | AP7: Inflow step 19 | AQ7: Inflow step 20 | AR7: Inflow step 21 | AS7: Inflow step 22 | AT7: Inflow step 23 | AU7: Inflow step 24
B8: Hover | C8: =0 -> 0 | D8: =0 -> 0 | E8: =1 -> 1 | F8: 1 | G8: =C8/3.6 -> 0 | H8: =IF(Inputs!E27="OK",0.5*Inputs!C27*Inputs!C58*G8^2,NA()) -> 0 | I8: =IF(F8=0,0,H8+Inputs!C55*D8) -> 0 | J8: =IF(F8=0,0,IF(AND(ISNUMBER(E8),E8>=1,E8<=10),Inputs!C56*E8,NA())) -> 11.437006 | K8: =SQRT(I8^2+J8^2) -> 11.437006 | L8: =IF(F8=0,0,DEGREES(ATAN(I8/J8))) -> 0 | M8: =IF(F8=0,0,G8*I8/K8) -> 0 | N8: =IF(F8=0,0,G8*J8/K8) -> 0 | O8: =IF(F8=0,0,IF(Inputs!E27="OK",SQRT(K8/(2*Inputs!C27*Inputs!C57)),NA())) -> 9.5983032 | P8: =AU8 -> 9.5983027 | Q8: =K8*P8 -> 109.77584 | R8: =I8*G8 -> 0 | S8: =IF(F8=0,0,IF(Inputs!E30="OK",SUM(Q8:R8)/Inputs!C30,NA())) -> 168.88591 | T8: =IF(AND(Inputs!E31="OK",Inputs!E32="OK"),S8/Inputs!C31+Inputs!C32,NA()) -> 205.65101 | U8: =T8/Inputs!C62 -> 9.7929053 | V8: =IF(Inputs!E25="OK",(T8-Inputs!C32)/Inputs!C25,NA()) -> 46.912753 | W8: =IF(F8=0,0,(P8*SQRT(N8^2+(M8+P8)^2)-O8^2)/O8^2) -> -1.1920929e-07 | X8: =$O8/2 -> 4.7991516 | Y8: =X8+IF(X8*SQRT($N8^2+($M8+X8)^2)<$O8^2,1,-1)*$O8/2^2 -> 7.1987274 | Z8: =Y8+IF(Y8*SQRT($N8^2+($M8+Y8)^2)<$O8^2,1,-1)*$O8/2^3 -> 8.3985153 | AA8: =Z8+IF(Z8*SQRT($N8^2+($M8+Z8)^2)<$O8^2,1,-1)*$O8/2^4 -> 8.9984093 | AB8: =AA8+IF(AA8*SQRT($N8^2+($M8+AA8)^2)<$O8^2,1,-1)*$O8/2^5 -> 9.2983563 | AC8: =AB8+IF(AB8*SQRT($N8^2+($M8+AB8)^2)<$O8^2,1,-1)*$O8/2^6 -> 9.4483298 | AD8: =AC8+IF(AC8*SQRT($N8^2+($M8+AC8)^2)<$O8^2,1,-1)*$O8/2^7 -> 9.5233165 | AE8: =AD8+IF(AD8*SQRT($N8^2+($M8+AD8)^2)<$O8^2,1,-1)*$O8/2^8 -> 9.5608099 | AF8: =AE8+IF(AE8*SQRT($N8^2+($M8+AE8)^2)<$O8^2,1,-1)*$O8/2^9 -> 9.5795566 | AG8: =AF8+IF(AF8*SQRT($N8^2+($M8+AF8)^2)<$O8^2,1,-1)*$O8/2^10 -> 9.5889299 | AH8: =AG8+IF(AG8*SQRT($N8^2+($M8+AG8)^2)<$O8^2,1,-1)*$O8/2^11 -> 9.5936166 | AI8: =AH8+IF(AH8*SQRT($N8^2+($M8+AH8)^2)<$O8^2,1,-1)*$O8/2^12 -> 9.5959599 | AJ8: =AI8+IF(AI8*SQRT($N8^2+($M8+AI8)^2)<$O8^2,1,-1)*$O8/2^13 -> 9.5971316 | AK8: =AJ8+IF(AJ8*SQRT($N8^2+($M8+AJ8)^2)<$O8^2,1,-1)*$O8/2^14 -> 9.5977174 | AL8: =AK8+IF(AK8*SQRT($N8^2+($M8+AK8)^2)<$O8^2,1,-1)*$O8/2^15 -> 9.5980103 | AM8: =AL8+IF(AL8*SQRT($N8^2+($M8+AL8)^2)<$O8^2,1,-1)*$O8/2^16 -> 9.5981568 | AN8: =AM8+IF(AM8*SQRT($N8^2+($M8+AM8)^2)<$O8^2,1,-1)*$O8/2^17 -> 9.59823 | AO8: =AN8+IF(AN8*SQRT($N8^2+($M8+AN8)^2)<$O8^2,1,-1)*$O8/2^18 -> 9.5982666 | AP8: =AO8+IF(AO8*SQRT($N8^2+($M8+AO8)^2)<$O8^2,1,-1)*$O8/2^19 -> 9.5982849 | AQ8: =AP8+IF(AP8*SQRT($N8^2+($M8+AP8)^2)<$O8^2,1,-1)*$O8/2^20 -> 9.5982941 | AR8: =AQ8+IF(AQ8*SQRT($N8^2+($M8+AQ8)^2)<$O8^2,1,-1)*$O8/2^21 -> 9.5982987 | AS8: =AR8+IF(AR8*SQRT($N8^2+($M8+AR8)^2)<$O8^2,1,-1)*$O8/2^22 -> 9.598301 | AT8: =AS8+IF(AS8*SQRT($N8^2+($M8+AS8)^2)<$O8^2,1,-1)*$O8/2^23 -> 9.5983021 | AU8: =AT8+IF(AT8*SQRT($N8^2+($M8+AT8)^2)<$O8^2,1,-1)*$O8/2^24 -> 9.5983027
B9: Target: steady level | C9: =IF(Inputs!E33="OK",Inputs!C33,NA()) -> 300 | D9: =0 -> 0 | E9: =1 -> 1 | F9: 1 | G9: =C9/3.6 -> 83.333333 | H9: =IF(Inputs!E27="OK",0.5*Inputs!C27*Inputs!C58*G9^2,NA()) -> 27.222222 | I9: =IF(F9=0,0,H9+Inputs!C55*D9) -> 27.222222 | J9: =IF(F9=0,0,IF(AND(ISNUMBER(E9),E9>=1,E9<=10),Inputs!C56*E9,NA())) -> 11.437006 | K9: =SQRT(I9^2+J9^2) -> 29.527182 | L9: =IF(F9=0,0,DEGREES(ATAN(I9/J9))) -> 67.211024 | M9: =IF(F9=0,0,G9*I9/K9) -> 76.828141 | N9: =IF(F9=0,0,G9*J9/K9) -> 32.278183 | O9: =IF(F9=0,0,IF(Inputs!E27="OK",SQRT(K9/(2*Inputs!C27*Inputs!C57)),NA())) -> 15.422305 | P9: =AU9 -> 2.7691153 | Q9: =K9*P9 -> 81.764171 | R9: =I9*G9 -> 2268.5185 | S9: =IF(F9=0,0,IF(Inputs!E30="OK",SUM(Q9:R9)/Inputs!C30,NA())) -> 3615.8195 | T9: =IF(AND(Inputs!E31="OK",Inputs!E32="OK"),S9/Inputs!C31+Inputs!C32,NA()) -> 4035.5772 | U9: =T9/Inputs!C62 -> 192.17035 | V9: =IF(Inputs!E25="OK",(T9-Inputs!C32)/Inputs!C25,NA()) -> 1004.3943 | W9: =IF(F9=0,0,(P9*SQRT(N9^2+(M9+P9)^2)-O9^2)/O9^2) -> 2.6389039e-07 | X9: =$O9/2 -> 7.7111527 | Y9: =X9+IF(X9*SQRT($N9^2+($M9+X9)^2)<$O9^2,1,-1)*$O9/2^2 -> 3.8555764 | Z9: =Y9+IF(Y9*SQRT($N9^2+($M9+Y9)^2)<$O9^2,1,-1)*$O9/2^3 -> 1.9277882 | AA9: =Z9+IF(Z9*SQRT($N9^2+($M9+Z9)^2)<$O9^2,1,-1)*$O9/2^4 -> 2.8916823 | AB9: =AA9+IF(AA9*SQRT($N9^2+($M9+AA9)^2)<$O9^2,1,-1)*$O9/2^5 -> 2.4097352 | AC9: =AB9+IF(AB9*SQRT($N9^2+($M9+AB9)^2)<$O9^2,1,-1)*$O9/2^6 -> 2.6507088 | AD9: =AC9+IF(AC9*SQRT($N9^2+($M9+AC9)^2)<$O9^2,1,-1)*$O9/2^7 -> 2.7711955 | AE9: =AD9+IF(AD9*SQRT($N9^2+($M9+AD9)^2)<$O9^2,1,-1)*$O9/2^8 -> 2.7109521 | AF9: =AE9+IF(AE9*SQRT($N9^2+($M9+AE9)^2)<$O9^2,1,-1)*$O9/2^9 -> 2.7410738 | AG9: =AF9+IF(AF9*SQRT($N9^2+($M9+AF9)^2)<$O9^2,1,-1)*$O9/2^10 -> 2.7561347 | AH9: =AG9+IF(AG9*SQRT($N9^2+($M9+AG9)^2)<$O9^2,1,-1)*$O9/2^11 -> 2.7636651 | AI9: =AH9+IF(AH9*SQRT($N9^2+($M9+AH9)^2)<$O9^2,1,-1)*$O9/2^12 -> 2.7674303 | AJ9: =AI9+IF(AI9*SQRT($N9^2+($M9+AI9)^2)<$O9^2,1,-1)*$O9/2^13 -> 2.7693129 | AK9: =AJ9+IF(AJ9*SQRT($N9^2+($M9+AJ9)^2)<$O9^2,1,-1)*$O9/2^14 -> 2.7683716 | AL9: =AK9+IF(AK9*SQRT($N9^2+($M9+AK9)^2)<$O9^2,1,-1)*$O9/2^15 -> 2.7688423 | AM9: =AL9+IF(AL9*SQRT($N9^2+($M9+AL9)^2)<$O9^2,1,-1)*$O9/2^16 -> 2.7690776 | AN9: =AM9+IF(AM9*SQRT($N9^2+($M9+AM9)^2)<$O9^2,1,-1)*$O9/2^17 -> 2.7691952 | AO9: =AN9+IF(AN9*SQRT($N9^2+($M9+AN9)^2)<$O9^2,1,-1)*$O9/2^18 -> 2.7691364 | AP9: =AO9+IF(AO9*SQRT($N9^2+($M9+AO9)^2)<$O9^2,1,-1)*$O9/2^19 -> 2.769107 | AQ9: =AP9+IF(AP9*SQRT($N9^2+($M9+AP9)^2)<$O9^2,1,-1)*$O9/2^20 -> 2.7691217 | AR9: =AQ9+IF(AQ9*SQRT($N9^2+($M9+AQ9)^2)<$O9^2,1,-1)*$O9/2^21 -> 2.7691144 | AS9: =AR9+IF(AR9*SQRT($N9^2+($M9+AR9)^2)<$O9^2,1,-1)*$O9/2^22 -> 2.769118 | AT9: =AS9+IF(AS9*SQRT($N9^2+($M9+AS9)^2)<$O9^2,1,-1)*$O9/2^23 -> 2.7691162 | AU9: =AT9+IF(AT9*SQRT($N9^2+($M9+AT9)^2)<$O9^2,1,-1)*$O9/2^24 -> 2.7691153
C11: Airspeed (km/h) | K11: Thrust required (N) | T11: Electrical power (W)
B12: Speed sweep 1 | C12: =IF(AND(Inputs!E33="OK",Inputs!E34="OK"),Inputs!C33*Inputs!C34*0/20,NA()) -> 0 | D12: =0 -> 0 | E12: =1 -> 1 | F12: 1 | G12: =C12/3.6 -> 0 | H12: =IF(Inputs!E27="OK",0.5*Inputs!C27*Inputs!C58*G12^2,NA()) -> 0 | I12: =IF(F12=0,0,H12+Inputs!C55*D12) -> 0 | J12: =IF(F12=0,0,IF(AND(ISNUMBER(E12),E12>=1,E12<=10),Inputs!C56*E12,NA())) -> 11.437006 | K12: =SQRT(I12^2+J12^2) -> 11.437006 | L12: =IF(F12=0,0,DEGREES(ATAN(I12/J12))) -> 0 | M12: =IF(F12=0,0,G12*I12/K12) -> 0 | N12: =IF(F12=0,0,G12*J12/K12) -> 0 | O12: =IF(F12=0,0,IF(Inputs!E27="OK",SQRT(K12/(2*Inputs!C27*Inputs!C57)),NA())) -> 9.5983032 | P12: =AU12 -> 9.5983027 | Q12: =K12*P12 -> 109.77584 | R12: =I12*G12 -> 0 | S12: =IF(F12=0,0,IF(Inputs!E30="OK",SUM(Q12:R12)/Inputs!C30,NA())) -> 168.88591 | T12: =IF(AND(Inputs!E31="OK",Inputs!E32="OK"),S12/Inputs!C31+Inputs!C32,NA()) -> 205.65101 | U12: =T12/Inputs!C62 -> 9.7929053 | V12: =IF(Inputs!E25="OK",(T12-Inputs!C32)/Inputs!C25,NA()) -> 46.912753 | W12: =IF(F12=0,0,(P12*SQRT(N12^2+(M12+P12)^2)-O12^2)/O12^2) -> -1.1920929e-07 | X12: =$O12/2 -> 4.7991516 | Y12: =X12+IF(X12*SQRT($N12^2+($M12+X12)^2)<$O12^2,1,-1)*$O12/2^2 -> 7.1987274 | Z12: =Y12+IF(Y12*SQRT($N12^2+($M12+Y12)^2)<$O12^2,1,-1)*$O12/2^3 -> 8.3985153 | AA12: =Z12+IF(Z12*SQRT($N12^2+($M12+Z12)^2)<$O12^2,1,-1)*$O12/2^4 -> 8.9984093 | AB12: =AA12+IF(AA12*SQRT($N12^2+($M12+AA12)^2)<$O12^2,1,-1)*$O12/2^5 -> 9.2983563 | AC12: =AB12+IF(AB12*SQRT($N12^2+($M12+AB12)^2)<$O12^2,1,-1)*$O12/2^6 -> 9.4483298 | AD12: =AC12+IF(AC12*SQRT($N12^2+($M12+AC12)^2)<$O12^2,1,-1)*$O12/2^7 -> 9.5233165 | AE12: =AD12+IF(AD12*SQRT($N12^2+($M12+AD12)^2)<$O12^2,1,-1)*$O12/2^8 -> 9.5608099 | AF12: =AE12+IF(AE12*SQRT($N12^2+($M12+AE12)^2)<$O12^2,1,-1)*$O12/2^9 -> 9.5795566 | AG12: =AF12+IF(AF12*SQRT($N12^2+($M12+AF12)^2)<$O12^2,1,-1)*$O12/2^10 -> 9.5889299 | AH12: =AG12+IF(AG12*SQRT($N12^2+($M12+AG12)^2)<$O12^2,1,-1)*$O12/2^11 -> 9.5936166 | AI12: =AH12+IF(AH12*SQRT($N12^2+($M12+AH12)^2)<$O12^2,1,-1)*$O12/2^12 -> 9.5959599 | AJ12: =AI12+IF(AI12*SQRT($N12^2+($M12+AI12)^2)<$O12^2,1,-1)*$O12/2^13 -> 9.5971316 | AK12: =AJ12+IF(AJ12*SQRT($N12^2+($M12+AJ12)^2)<$O12^2,1,-1)*$O12/2^14 -> 9.5977174 | AL12: =AK12+IF(AK12*SQRT($N12^2+($M12+AK12)^2)<$O12^2,1,-1)*$O12/2^15 -> 9.5980103 | AM12: =AL12+IF(AL12*SQRT($N12^2+($M12+AL12)^2)<$O12^2,1,-1)*$O12/2^16 -> 9.5981568 | AN12: =AM12+IF(AM12*SQRT($N12^2+($M12+AM12)^2)<$O12^2,1,-1)*$O12/2^17 -> 9.59823 | AO12: =AN12+IF(AN12*SQRT($N12^2+($M12+AN12)^2)<$O12^2,1,-1)*$O12/2^18 -> 9.5982666 | AP12: =AO12+IF(AO12*SQRT($N12^2+($M12+AO12)^2)<$O12^2,1,-1)*$O12/2^19 -> 9.5982849 | AQ12: =AP12+IF(AP12*SQRT($N12^2+($M12+AP12)^2)<$O12^2,1,-1)*$O12/2^20 -> 9.5982941 | AR12: =AQ12+IF(AQ12*SQRT($N12^2+($M12+AQ12)^2)<$O12^2,1,-1)*$O12/2^21 -> 9.5982987 | AS12: =AR12+IF(AR12*SQRT($N12^2+($M12+AR12)^2)<$O12^2,1,-1)*$O12/2^22 -> 9.598301 | AT12: =AS12+IF(AS12*SQRT($N12^2+($M12+AS12)^2)<$O12^2,1,-1)*$O12/2^23 -> 9.5983021 | AU12: =AT12+IF(AT12*SQRT($N12^2+($M12+AT12)^2)<$O12^2,1,-1)*$O12/2^24 -> 9.5983027
B13: Speed sweep 2 | C13: =IF(AND(Inputs!E33="OK",Inputs!E34="OK"),Inputs!C33*Inputs!C34*1/20,NA()) -> 18 | D13: =0 -> 0 | E13: =1 -> 1 | F13: 1 | G13: =C13/3.6 -> 5 | H13: =IF(Inputs!E27="OK",0.5*Inputs!C27*Inputs!C58*G13^2,NA()) -> 0.098 | I13: =IF(F13=0,0,H13+Inputs!C55*D13) -> 0.098 | J13: =IF(F13=0,0,IF(AND(ISNUMBER(E13),E13>=1,E13<=10),Inputs!C56*E13,NA())) -> 11.437006 | K13: =SQRT(I13^2+J13^2) -> 11.437425 | L13: =IF(F13=0,0,DEGREES(ATAN(I13/J13))) -> 0.49093698 | M13: =IF(F13=0,0,G13*I13/K13) -> 0.042841809 | N13: =IF(F13=0,0,G13*J13/K13) -> 4.9998165 | O13: =IF(F13=0,0,IF(Inputs!E27="OK",SQRT(K13/(2*Inputs!C27*Inputs!C57)),NA())) -> 9.5984794 | P13: =AU13 -> 8.9523025 | Q13: =K13*P13 -> 102.39129 | R13: =I13*G13 -> 0.49 | S13: =IF(F13=0,0,IF(Inputs!E30="OK",SUM(Q13:R13)/Inputs!C30,NA())) -> 158.27891 | T13: =IF(AND(Inputs!E31="OK",Inputs!E32="OK"),S13/Inputs!C31+Inputs!C32,NA()) -> 193.86546 | U13: =T13/Inputs!C62 -> 9.2316884 | V13: =IF(Inputs!E25="OK",(T13-Inputs!C32)/Inputs!C25,NA()) -> 43.966364 | W13: =IF(F13=0,0,(P13*SQRT(N13^2+(M13+P13)^2)-O13^2)/O13^2) -> -8.4309875e-08 | X13: =$O13/2 -> 4.7992397 | Y13: =X13+IF(X13*SQRT($N13^2+($M13+X13)^2)<$O13^2,1,-1)*$O13/2^2 -> 7.1988596 | Z13: =Y13+IF(Y13*SQRT($N13^2+($M13+Y13)^2)<$O13^2,1,-1)*$O13/2^3 -> 8.3986695 | AA13: =Z13+IF(Z13*SQRT($N13^2+($M13+Z13)^2)<$O13^2,1,-1)*$O13/2^4 -> 8.9985745 | AB13: =AA13+IF(AA13*SQRT($N13^2+($M13+AA13)^2)<$O13^2,1,-1)*$O13/2^5 -> 8.698622 | AC13: =AB13+IF(AB13*SQRT($N13^2+($M13+AB13)^2)<$O13^2,1,-1)*$O13/2^6 -> 8.8485982 | AD13: =AC13+IF(AC13*SQRT($N13^2+($M13+AC13)^2)<$O13^2,1,-1)*$O13/2^7 -> 8.9235863 | AE13: =AD13+IF(AD13*SQRT($N13^2+($M13+AD13)^2)<$O13^2,1,-1)*$O13/2^8 -> 8.9610804 | AF13: =AE13+IF(AE13*SQRT($N13^2+($M13+AE13)^2)<$O13^2,1,-1)*$O13/2^9 -> 8.9423334 | AG13: =AF13+IF(AF13*SQRT($N13^2+($M13+AF13)^2)<$O13^2,1,-1)*$O13/2^10 -> 8.9517069 | AH13: =AG13+IF(AG13*SQRT($N13^2+($M13+AG13)^2)<$O13^2,1,-1)*$O13/2^11 -> 8.9563936 | AI13: =AH13+IF(AH13*SQRT($N13^2+($M13+AH13)^2)<$O13^2,1,-1)*$O13/2^12 -> 8.9540503 | AJ13: =AI13+IF(AI13*SQRT($N13^2+($M13+AI13)^2)<$O13^2,1,-1)*$O13/2^13 -> 8.9528786 | AK13: =AJ13+IF(AJ13*SQRT($N13^2+($M13+AJ13)^2)<$O13^2,1,-1)*$O13/2^14 -> 8.9522927 | AL13: =AK13+IF(AK13*SQRT($N13^2+($M13+AK13)^2)<$O13^2,1,-1)*$O13/2^15 -> 8.9525856 | AM13: =AL13+IF(AL13*SQRT($N13^2+($M13+AL13)^2)<$O13^2,1,-1)*$O13/2^16 -> 8.9524392 | AN13: =AM13+IF(AM13*SQRT($N13^2+($M13+AM13)^2)<$O13^2,1,-1)*$O13/2^17 -> 8.952366 | AO13: =AN13+IF(AN13*SQRT($N13^2+($M13+AN13)^2)<$O13^2,1,-1)*$O13/2^18 -> 8.9523293 | AP13: =AO13+IF(AO13*SQRT($N13^2+($M13+AO13)^2)<$O13^2,1,-1)*$O13/2^19 -> 8.952311 | AQ13: =AP13+IF(AP13*SQRT($N13^2+($M13+AP13)^2)<$O13^2,1,-1)*$O13/2^20 -> 8.9523019 | AR13: =AQ13+IF(AQ13*SQRT($N13^2+($M13+AQ13)^2)<$O13^2,1,-1)*$O13/2^21 -> 8.9523065 | AS13: =AR13+IF(AR13*SQRT($N13^2+($M13+AR13)^2)<$O13^2,1,-1)*$O13/2^22 -> 8.9523042 | AT13: =AS13+IF(AS13*SQRT($N13^2+($M13+AS13)^2)<$O13^2,1,-1)*$O13/2^23 -> 8.952303 | AU13: =AT13+IF(AT13*SQRT($N13^2+($M13+AT13)^2)<$O13^2,1,-1)*$O13/2^24 -> 8.9523025
B14: Speed sweep 3 | C14: =IF(AND(Inputs!E33="OK",Inputs!E34="OK"),Inputs!C33*Inputs!C34*2/20,NA()) -> 36 | D14: =0 -> 0 | E14: =1 -> 1 | F14: 1 | G14: =C14/3.6 -> 10 | H14: =IF(Inputs!E27="OK",0.5*Inputs!C27*Inputs!C58*G14^2,NA()) -> 0.392 | I14: =IF(F14=0,0,H14+Inputs!C55*D14) -> 0.392 | J14: =IF(F14=0,0,IF(AND(ISNUMBER(E14),E14>=1,E14<=10),Inputs!C56*E14,NA())) -> 11.437006 | K14: =SQRT(I14^2+J14^2) -> 11.443721 | L14: =IF(F14=0,0,DEGREES(ATAN(I14/J14))) -> 1.9630275 | M14: =IF(F14=0,0,G14*I14/K14) -> 0.34254591 | N14: =IF(F14=0,0,G14*J14/K14) -> 9.9941314 | O14: =IF(F14=0,0,IF(Inputs!E27="OK",SQRT(K14/(2*Inputs!C27*Inputs!C57)),NA())) -> 9.6011209 | P14: =AU14 -> 7.3198131 | Q14: =K14*P14 -> 83.765901 | R14: =I14*G14 -> 3.92 | S14: =IF(F14=0,0,IF(Inputs!E30="OK",SUM(Q14:R14)/Inputs!C30,NA())) -> 134.90139 | T14: =IF(AND(Inputs!E31="OK",Inputs!E32="OK"),S14/Inputs!C31+Inputs!C32,NA()) -> 167.89043 | U14: =T14/Inputs!C62 -> 7.9947824 | V14: =IF(Inputs!E25="OK",(T14-Inputs!C32)/Inputs!C25,NA()) -> 37.472607 | W14: =IF(F14=0,0,(P14*SQRT(N14^2+(M14+P14)^2)-O14^2)/O14^2) -> 1.0286638e-07 | X14: =$O14/2 -> 4.8005605 | Y14: =X14+IF(X14*SQRT($N14^2+($M14+X14)^2)<$O14^2,1,-1)*$O14/2^2 -> 7.2008407 | Z14: =Y14+IF(Y14*SQRT($N14^2+($M14+Y14)^2)<$O14^2,1,-1)*$O14/2^3 -> 8.4009808 | AA14: =Z14+IF(Z14*SQRT($N14^2+($M14+Z14)^2)<$O14^2,1,-1)*$O14/2^4 -> 7.8009107 | AB14: =AA14+IF(AA14*SQRT($N14^2+($M14+AA14)^2)<$O14^2,1,-1)*$O14/2^5 -> 7.5008757 | AC14: =AB14+IF(AB14*SQRT($N14^2+($M14+AB14)^2)<$O14^2,1,-1)*$O14/2^6 -> 7.3508582 | AD14: =AC14+IF(AC14*SQRT($N14^2+($M14+AC14)^2)<$O14^2,1,-1)*$O14/2^7 -> 7.2758494 | AE14: =AD14+IF(AD14*SQRT($N14^2+($M14+AD14)^2)<$O14^2,1,-1)*$O14/2^8 -> 7.3133538 | AF14: =AE14+IF(AE14*SQRT($N14^2+($M14+AE14)^2)<$O14^2,1,-1)*$O14/2^9 -> 7.332106 | AG14: =AF14+IF(AF14*SQRT($N14^2+($M14+AF14)^2)<$O14^2,1,-1)*$O14/2^10 -> 7.3227299 | AH14: =AG14+IF(AG14*SQRT($N14^2+($M14+AG14)^2)<$O14^2,1,-1)*$O14/2^11 -> 7.3180419 | AI14: =AH14+IF(AH14*SQRT($N14^2+($M14+AH14)^2)<$O14^2,1,-1)*$O14/2^12 -> 7.3203859 | AJ14: =AI14+IF(AI14*SQRT($N14^2+($M14+AI14)^2)<$O14^2,1,-1)*$O14/2^13 -> 7.3192139 | AK14: =AJ14+IF(AJ14*SQRT($N14^2+($M14+AJ14)^2)<$O14^2,1,-1)*$O14/2^14 -> 7.3197999 | AL14: =AK14+IF(AK14*SQRT($N14^2+($M14+AK14)^2)<$O14^2,1,-1)*$O14/2^15 -> 7.3200929 | AM14: =AL14+IF(AL14*SQRT($N14^2+($M14+AL14)^2)<$O14^2,1,-1)*$O14/2^16 -> 7.3199464 | AN14: =AM14+IF(AM14*SQRT($N14^2+($M14+AM14)^2)<$O14^2,1,-1)*$O14/2^17 -> 7.3198731 | AO14: =AN14+IF(AN14*SQRT($N14^2+($M14+AN14)^2)<$O14^2,1,-1)*$O14/2^18 -> 7.3198365 | AP14: =AO14+IF(AO14*SQRT($N14^2+($M14+AO14)^2)<$O14^2,1,-1)*$O14/2^19 -> 7.3198182 | AQ14: =AP14+IF(AP14*SQRT($N14^2+($M14+AP14)^2)<$O14^2,1,-1)*$O14/2^20 -> 7.319809 | AR14: =AQ14+IF(AQ14*SQRT($N14^2+($M14+AQ14)^2)<$O14^2,1,-1)*$O14/2^21 -> 7.3198136 | AS14: =AR14+IF(AR14*SQRT($N14^2+($M14+AR14)^2)<$O14^2,1,-1)*$O14/2^22 -> 7.3198113 | AT14: =AS14+IF(AS14*SQRT($N14^2+($M14+AS14)^2)<$O14^2,1,-1)*$O14/2^23 -> 7.3198125 | AU14: =AT14+IF(AT14*SQRT($N14^2+($M14+AT14)^2)<$O14^2,1,-1)*$O14/2^24 -> 7.3198131
B15: Speed sweep 4 | C15: =IF(AND(Inputs!E33="OK",Inputs!E34="OK"),Inputs!C33*Inputs!C34*3/20,NA()) -> 54 | D15: =0 -> 0 | E15: =1 -> 1 | F15: 1 | G15: =C15/3.6 -> 15 | H15: =IF(Inputs!E27="OK",0.5*Inputs!C27*Inputs!C58*G15^2,NA()) -> 0.882 | I15: =IF(F15=0,0,H15+Inputs!C55*D15) -> 0.882 | J15: =IF(F15=0,0,IF(AND(ISNUMBER(E15),E15>=1,E15<=10),Inputs!C56*E15,NA())) -> 11.437006 | K15: =SQRT(I15^2+J15^2) -> 11.470964 | L15: =IF(F15=0,0,DEGREES(ATAN(I15/J15))) -> 4.4098128 | M15: =IF(F15=0,0,G15*I15/K15) -> 1.1533468 | N15: =IF(F15=0,0,G15*J15/K15) -> 14.955594 | O15: =IF(F15=0,0,IF(Inputs!E27="OK",SQRT(K15/(2*Inputs!C27*Inputs!C57)),NA())) -> 9.6125423 | P15: =AU15 -> 5.6270578 | Q15: =K15*P15 -> 64.547778 | R15: =I15*G15 -> 13.23 | S15: =IF(F15=0,0,IF(Inputs!E30="OK",SUM(Q15:R15)/Inputs!C30,NA())) -> 119.65812 | T15: =IF(AND(Inputs!E31="OK",Inputs!E32="OK"),S15/Inputs!C31+Inputs!C32,NA()) -> 150.95347 | U15: =T15/Inputs!C62 -> 7.1882604 | V15: =IF(Inputs!E25="OK",(T15-Inputs!C32)/Inputs!C25,NA()) -> 33.238367 | W15: =IF(F15=0,0,(P15*SQRT(N15^2+(M15+P15)^2)-O15^2)/O15^2) -> -7.0957456e-08 | X15: =$O15/2 -> 4.8062711 | Y15: =X15+IF(X15*SQRT($N15^2+($M15+X15)^2)<$O15^2,1,-1)*$O15/2^2 -> 7.2094067 | Z15: =Y15+IF(Y15*SQRT($N15^2+($M15+Y15)^2)<$O15^2,1,-1)*$O15/2^3 -> 6.0078389 | AA15: =Z15+IF(Z15*SQRT($N15^2+($M15+Z15)^2)<$O15^2,1,-1)*$O15/2^4 -> 5.407055 | AB15: =AA15+IF(AA15*SQRT($N15^2+($M15+AA15)^2)<$O15^2,1,-1)*$O15/2^5 -> 5.707447 | AC15: =AB15+IF(AB15*SQRT($N15^2+($M15+AB15)^2)<$O15^2,1,-1)*$O15/2^6 -> 5.557251 | AD15: =AC15+IF(AC15*SQRT($N15^2+($M15+AC15)^2)<$O15^2,1,-1)*$O15/2^7 -> 5.632349 | AE15: =AD15+IF(AD15*SQRT($N15^2+($M15+AD15)^2)<$O15^2,1,-1)*$O15/2^8 -> 5.5948 | AF15: =AE15+IF(AE15*SQRT($N15^2+($M15+AE15)^2)<$O15^2,1,-1)*$O15/2^9 -> 5.6135745 | AG15: =AF15+IF(AF15*SQRT($N15^2+($M15+AF15)^2)<$O15^2,1,-1)*$O15/2^10 -> 5.6229617 | AH15: =AG15+IF(AG15*SQRT($N15^2+($M15+AG15)^2)<$O15^2,1,-1)*$O15/2^11 -> 5.6276554 | AI15: =AH15+IF(AH15*SQRT($N15^2+($M15+AH15)^2)<$O15^2,1,-1)*$O15/2^12 -> 5.6253086 | AJ15: =AI15+IF(AI15*SQRT($N15^2+($M15+AI15)^2)<$O15^2,1,-1)*$O15/2^13 -> 5.626482 | AK15: =AJ15+IF(AJ15*SQRT($N15^2+($M15+AJ15)^2)<$O15^2,1,-1)*$O15/2^14 -> 5.6270687 | AL15: =AK15+IF(AK15*SQRT($N15^2+($M15+AK15)^2)<$O15^2,1,-1)*$O15/2^15 -> 5.6267753 | AM15: =AL15+IF(AL15*SQRT($N15^2+($M15+AL15)^2)<$O15^2,1,-1)*$O15/2^16 -> 5.626922 | AN15: =AM15+IF(AM15*SQRT($N15^2+($M15+AM15)^2)<$O15^2,1,-1)*$O15/2^17 -> 5.6269953 | AO15: =AN15+IF(AN15*SQRT($N15^2+($M15+AN15)^2)<$O15^2,1,-1)*$O15/2^18 -> 5.627032 | AP15: =AO15+IF(AO15*SQRT($N15^2+($M15+AO15)^2)<$O15^2,1,-1)*$O15/2^19 -> 5.6270503 | AQ15: =AP15+IF(AP15*SQRT($N15^2+($M15+AP15)^2)<$O15^2,1,-1)*$O15/2^20 -> 5.6270595 | AR15: =AQ15+IF(AQ15*SQRT($N15^2+($M15+AQ15)^2)<$O15^2,1,-1)*$O15/2^21 -> 5.6270549 | AS15: =AR15+IF(AR15*SQRT($N15^2+($M15+AR15)^2)<$O15^2,1,-1)*$O15/2^22 -> 5.6270572 | AT15: =AS15+IF(AS15*SQRT($N15^2+($M15+AS15)^2)<$O15^2,1,-1)*$O15/2^23 -> 5.6270584 | AU15: =AT15+IF(AT15*SQRT($N15^2+($M15+AT15)^2)<$O15^2,1,-1)*$O15/2^24 -> 5.6270578
B16: Speed sweep 5 | C16: =IF(AND(Inputs!E33="OK",Inputs!E34="OK"),Inputs!C33*Inputs!C34*4/20,NA()) -> 72 | D16: =0 -> 0 | E16: =1 -> 1 | F16: 1 | G16: =C16/3.6 -> 20 | H16: =IF(Inputs!E27="OK",0.5*Inputs!C27*Inputs!C58*G16^2,NA()) -> 1.568 | I16: =IF(F16=0,0,H16+Inputs!C55*D16) -> 1.568 | J16: =IF(F16=0,0,IF(AND(ISNUMBER(E16),E16>=1,E16<=10),Inputs!C56*E16,NA())) -> 11.437006 | K16: =SQRT(I16^2+J16^2) -> 11.543991 | L16: =IF(F16=0,0,DEGREES(ATAN(I16/J16))) -> 7.806516 | M16: =IF(F16=0,0,G16*I16/K16) -> 2.7165649 | N16: =IF(F16=0,0,G16*J16/K16) -> 19.814648 | O16: =IF(F16=0,0,IF(Inputs!E27="OK",SQRT(K16/(2*Inputs!C27*Inputs!C57)),NA())) -> 9.6430914 | P16: =AU16 -> 4.4156174 | Q16: =K16*P16 -> 50.973846 | R16: =I16*G16 -> 31.36 | S16: =IF(F16=0,0,IF(Inputs!E30="OK",SUM(Q16:R16)/Inputs!C30,NA())) -> 126.66746 | T16: =IF(AND(Inputs!E31="OK",Inputs!E32="OK"),S16/Inputs!C31+Inputs!C32,NA()) -> 158.74162 | U16: =T16/Inputs!C62 -> 7.5591246 | V16: =IF(Inputs!E25="OK",(T16-Inputs!C32)/Inputs!C25,NA()) -> 35.185404 | W16: =IF(F16=0,0,(P16*SQRT(N16^2+(M16+P16)^2)-O16^2)/O16^2) -> -1.0584795e-07 | X16: =$O16/2 -> 4.8215457 | Y16: =X16+IF(X16*SQRT($N16^2+($M16+X16)^2)<$O16^2,1,-1)*$O16/2^2 -> 2.4107729 | Z16: =Y16+IF(Y16*SQRT($N16^2+($M16+Y16)^2)<$O16^2,1,-1)*$O16/2^3 -> 3.6161593 | AA16: =Z16+IF(Z16*SQRT($N16^2+($M16+Z16)^2)<$O16^2,1,-1)*$O16/2^4 -> 4.2188525 | AB16: =AA16+IF(AA16*SQRT($N16^2+($M16+AA16)^2)<$O16^2,1,-1)*$O16/2^5 -> 4.5201991 | AC16: =AB16+IF(AB16*SQRT($N16^2+($M16+AB16)^2)<$O16^2,1,-1)*$O16/2^6 -> 4.3695258 | AD16: =AC16+IF(AC16*SQRT($N16^2+($M16+AC16)^2)<$O16^2,1,-1)*$O16/2^7 -> 4.4448624 | AE16: =AD16+IF(AD16*SQRT($N16^2+($M16+AD16)^2)<$O16^2,1,-1)*$O16/2^8 -> 4.4071941 | AF16: =AE16+IF(AE16*SQRT($N16^2+($M16+AE16)^2)<$O16^2,1,-1)*$O16/2^9 -> 4.4260283 | AG16: =AF16+IF(AF16*SQRT($N16^2+($M16+AF16)^2)<$O16^2,1,-1)*$O16/2^10 -> 4.4166112 | AH16: =AG16+IF(AG16*SQRT($N16^2+($M16+AG16)^2)<$O16^2,1,-1)*$O16/2^11 -> 4.4119027 | AI16: =AH16+IF(AH16*SQRT($N16^2+($M16+AH16)^2)<$O16^2,1,-1)*$O16/2^12 -> 4.4142569 | AJ16: =AI16+IF(AI16*SQRT($N16^2+($M16+AI16)^2)<$O16^2,1,-1)*$O16/2^13 -> 4.4154341 | AK16: =AJ16+IF(AJ16*SQRT($N16^2+($M16+AJ16)^2)<$O16^2,1,-1)*$O16/2^14 -> 4.4160226 | AL16: =AK16+IF(AK16*SQRT($N16^2+($M16+AK16)^2)<$O16^2,1,-1)*$O16/2^15 -> 4.4157284 | AM16: =AL16+IF(AL16*SQRT($N16^2+($M16+AL16)^2)<$O16^2,1,-1)*$O16/2^16 -> 4.4155812 | AN16: =AM16+IF(AM16*SQRT($N16^2+($M16+AM16)^2)<$O16^2,1,-1)*$O16/2^17 -> 4.4156548 | AO16: =AN16+IF(AN16*SQRT($N16^2+($M16+AN16)^2)<$O16^2,1,-1)*$O16/2^18 -> 4.415618 | AP16: =AO16+IF(AO16*SQRT($N16^2+($M16+AO16)^2)<$O16^2,1,-1)*$O16/2^19 -> 4.4155996 | AQ16: =AP16+IF(AP16*SQRT($N16^2+($M16+AP16)^2)<$O16^2,1,-1)*$O16/2^20 -> 4.4156088 | AR16: =AQ16+IF(AQ16*SQRT($N16^2+($M16+AQ16)^2)<$O16^2,1,-1)*$O16/2^21 -> 4.4156134 | AS16: =AR16+IF(AR16*SQRT($N16^2+($M16+AR16)^2)<$O16^2,1,-1)*$O16/2^22 -> 4.4156157 | AT16: =AS16+IF(AS16*SQRT($N16^2+($M16+AS16)^2)<$O16^2,1,-1)*$O16/2^23 -> 4.4156168 | AU16: =AT16+IF(AT16*SQRT($N16^2+($M16+AT16)^2)<$O16^2,1,-1)*$O16/2^24 -> 4.4156174
B17: Speed sweep 6 | C17: =IF(AND(Inputs!E33="OK",Inputs!E34="OK"),Inputs!C33*Inputs!C34*5/20,NA()) -> 90 | D17: =0 -> 0 | E17: =1 -> 1 | F17: 1 | G17: =C17/3.6 -> 25 | H17: =IF(Inputs!E27="OK",0.5*Inputs!C27*Inputs!C58*G17^2,NA()) -> 2.45 | I17: =IF(F17=0,0,H17+Inputs!C55*D17) -> 2.45 | J17: =IF(F17=0,0,IF(AND(ISNUMBER(E17),E17>=1,E17<=10),Inputs!C56*E17,NA())) -> 11.437006 | K17: =SQRT(I17^2+J17^2) -> 11.696478 | L17: =IF(F17=0,0,DEGREES(ATAN(I17/J17))) -> 12.090988 | M17: =IF(F17=0,0,G17*I17/K17) -> 5.2366191 | N17: =IF(F17=0,0,G17*J17/K17) -> 24.445405 | O17: =IF(F17=0,0,IF(Inputs!E27="OK",SQRT(K17/(2*Inputs!C27*Inputs!C57)),NA())) -> 9.7065714 | P17: =AU17 -> 3.6235362 | Q17: =K17*P17 -> 42.382611 | R17: =I17*G17 -> 61.25 | S17: =IF(F17=0,0,IF(Inputs!E30="OK",SUM(Q17:R17)/Inputs!C30,NA())) -> 159.43479 | T17: =IF(AND(Inputs!E31="OK",Inputs!E32="OK"),S17/Inputs!C31+Inputs!C32,NA()) -> 195.14976 | U17: =T17/Inputs!C62 -> 9.2928458 | V17: =IF(Inputs!E25="OK",(T17-Inputs!C32)/Inputs!C25,NA()) -> 44.28744 | W17: =IF(F17=0,0,(P17*SQRT(N17^2+(M17+P17)^2)-O17^2)/O17^2) -> -1.9373448e-08 | X17: =$O17/2 -> 4.8532857 | Y17: =X17+IF(X17*SQRT($N17^2+($M17+X17)^2)<$O17^2,1,-1)*$O17/2^2 -> 2.4266429 | Z17: =Y17+IF(Y17*SQRT($N17^2+($M17+Y17)^2)<$O17^2,1,-1)*$O17/2^3 -> 3.6399643 | AA17: =Z17+IF(Z17*SQRT($N17^2+($M17+Z17)^2)<$O17^2,1,-1)*$O17/2^4 -> 3.0333036 | AB17: =AA17+IF(AA17*SQRT($N17^2+($M17+AA17)^2)<$O17^2,1,-1)*$O17/2^5 -> 3.3366339 | AC17: =AB17+IF(AB17*SQRT($N17^2+($M17+AB17)^2)<$O17^2,1,-1)*$O17/2^6 -> 3.4882991 | AD17: =AC17+IF(AC17*SQRT($N17^2+($M17+AC17)^2)<$O17^2,1,-1)*$O17/2^7 -> 3.5641317 | AE17: =AD17+IF(AD17*SQRT($N17^2+($M17+AD17)^2)<$O17^2,1,-1)*$O17/2^8 -> 3.602048 | AF17: =AE17+IF(AE17*SQRT($N17^2+($M17+AE17)^2)<$O17^2,1,-1)*$O17/2^9 -> 3.6210061 | AG17: =AF17+IF(AF17*SQRT($N17^2+($M17+AF17)^2)<$O17^2,1,-1)*$O17/2^10 -> 3.6304852 | AH17: =AG17+IF(AG17*SQRT($N17^2+($M17+AG17)^2)<$O17^2,1,-1)*$O17/2^11 -> 3.6257457 | AI17: =AH17+IF(AH17*SQRT($N17^2+($M17+AH17)^2)<$O17^2,1,-1)*$O17/2^12 -> 3.6233759 | AJ17: =AI17+IF(AI17*SQRT($N17^2+($M17+AI17)^2)<$O17^2,1,-1)*$O17/2^13 -> 3.6245608 | AK17: =AJ17+IF(AJ17*SQRT($N17^2+($M17+AJ17)^2)<$O17^2,1,-1)*$O17/2^14 -> 3.6239683 | AL17: =AK17+IF(AK17*SQRT($N17^2+($M17+AK17)^2)<$O17^2,1,-1)*$O17/2^15 -> 3.6236721 | AM17: =AL17+IF(AL17*SQRT($N17^2+($M17+AL17)^2)<$O17^2,1,-1)*$O17/2^16 -> 3.623524 | AN17: =AM17+IF(AM17*SQRT($N17^2+($M17+AM17)^2)<$O17^2,1,-1)*$O17/2^17 -> 3.6235981 | AO17: =AN17+IF(AN17*SQRT($N17^2+($M17+AN17)^2)<$O17^2,1,-1)*$O17/2^18 -> 3.623561 | AP17: =AO17+IF(AO17*SQRT($N17^2+($M17+AO17)^2)<$O17^2,1,-1)*$O17/2^19 -> 3.6235425 | AQ17: =AP17+IF(AP17*SQRT($N17^2+($M17+AP17)^2)<$O17^2,1,-1)*$O17/2^20 -> 3.6235333 | AR17: =AQ17+IF(AQ17*SQRT($N17^2+($M17+AQ17)^2)<$O17^2,1,-1)*$O17/2^21 -> 3.6235379 | AS17: =AR17+IF(AR17*SQRT($N17^2+($M17+AR17)^2)<$O17^2,1,-1)*$O17/2^22 -> 3.6235356 | AT17: =AS17+IF(AS17*SQRT($N17^2+($M17+AS17)^2)<$O17^2,1,-1)*$O17/2^23 -> 3.6235367 | AU17: =AT17+IF(AT17*SQRT($N17^2+($M17+AT17)^2)<$O17^2,1,-1)*$O17/2^24 -> 3.6235362
B18: Speed sweep 7 | C18: =IF(AND(Inputs!E33="OK",Inputs!E34="OK"),Inputs!C33*Inputs!C34*6/20,NA()) -> 108 | D18: =0 -> 0 | E18: =1 -> 1 | F18: 1 | G18: =C18/3.6 -> 30 | H18: =IF(Inputs!E27="OK",0.5*Inputs!C27*Inputs!C58*G18^2,NA()) -> 3.528 | I18: =IF(F18=0,0,H18+Inputs!C55*D18) -> 3.528 | J18: =IF(F18=0,0,IF(AND(ISNUMBER(E18),E18>=1,E18<=10),Inputs!C56*E18,NA())) -> 11.437006 | K18: =SQRT(I18^2+J18^2) -> 11.968788 | L18: =IF(F18=0,0,DEGREES(ATAN(I18/J18))) -> 17.143548 | M18: =IF(F18=0,0,G18*I18/K18) -> 8.8430008 | N18: =IF(F18=0,0,G18*J18/K18) -> 28.667078 | O18: =IF(F18=0,0,IF(Inputs!E27="OK",SQRT(K18/(2*Inputs!C27*Inputs!C57)),NA())) -> 9.8189124 | P18: =AU18 -> 3.1043218 | Q18: =K18*P18 -> 37.154969 | R18: =I18*G18 -> 105.84 | S18: =IF(F18=0,0,IF(Inputs!E30="OK",SUM(Q18:R18)/Inputs!C30,NA())) -> 219.99226 | T18: =IF(AND(Inputs!E31="OK",Inputs!E32="OK"),S18/Inputs!C31+Inputs!C32,NA()) -> 262.43584 | U18: =T18/Inputs!C62 -> 12.496945 | V18: =IF(Inputs!E25="OK",(T18-Inputs!C32)/Inputs!C25,NA()) -> 61.108961 | W18: =IF(F18=0,0,(P18*SQRT(N18^2+(M18+P18)^2)-O18^2)/O18^2) -> 1.3262767e-07 | X18: =$O18/2 -> 4.9094562 | Y18: =X18+IF(X18*SQRT($N18^2+($M18+X18)^2)<$O18^2,1,-1)*$O18/2^2 -> 2.4547281 | Z18: =Y18+IF(Y18*SQRT($N18^2+($M18+Y18)^2)<$O18^2,1,-1)*$O18/2^3 -> 3.6820921 | AA18: =Z18+IF(Z18*SQRT($N18^2+($M18+Z18)^2)<$O18^2,1,-1)*$O18/2^4 -> 3.0684101 | AB18: =AA18+IF(AA18*SQRT($N18^2+($M18+AA18)^2)<$O18^2,1,-1)*$O18/2^5 -> 3.3752511 | AC18: =AB18+IF(AB18*SQRT($N18^2+($M18+AB18)^2)<$O18^2,1,-1)*$O18/2^6 -> 3.2218306 | AD18: =AC18+IF(AC18*SQRT($N18^2+($M18+AC18)^2)<$O18^2,1,-1)*$O18/2^7 -> 3.1451204 | AE18: =AD18+IF(AD18*SQRT($N18^2+($M18+AD18)^2)<$O18^2,1,-1)*$O18/2^8 -> 3.1067652 | AF18: =AE18+IF(AE18*SQRT($N18^2+($M18+AE18)^2)<$O18^2,1,-1)*$O18/2^9 -> 3.0875877 | AG18: =AF18+IF(AF18*SQRT($N18^2+($M18+AF18)^2)<$O18^2,1,-1)*$O18/2^10 -> 3.0971765 | AH18: =AG18+IF(AG18*SQRT($N18^2+($M18+AG18)^2)<$O18^2,1,-1)*$O18/2^11 -> 3.1019708 | AI18: =AH18+IF(AH18*SQRT($N18^2+($M18+AH18)^2)<$O18^2,1,-1)*$O18/2^12 -> 3.104368 | AJ18: =AI18+IF(AI18*SQRT($N18^2+($M18+AI18)^2)<$O18^2,1,-1)*$O18/2^13 -> 3.1031694 | AK18: =AJ18+IF(AJ18*SQRT($N18^2+($M18+AJ18)^2)<$O18^2,1,-1)*$O18/2^14 -> 3.1037687 | AL18: =AK18+IF(AK18*SQRT($N18^2+($M18+AK18)^2)<$O18^2,1,-1)*$O18/2^15 -> 3.1040684 | AM18: =AL18+IF(AL18*SQRT($N18^2+($M18+AL18)^2)<$O18^2,1,-1)*$O18/2^16 -> 3.1042182 | AN18: =AM18+IF(AM18*SQRT($N18^2+($M18+AM18)^2)<$O18^2,1,-1)*$O18/2^17 -> 3.1042931 | AO18: =AN18+IF(AN18*SQRT($N18^2+($M18+AN18)^2)<$O18^2,1,-1)*$O18/2^18 -> 3.1043306 | AP18: =AO18+IF(AO18*SQRT($N18^2+($M18+AO18)^2)<$O18^2,1,-1)*$O18/2^19 -> 3.1043119 | AQ18: =AP18+IF(AP18*SQRT($N18^2+($M18+AP18)^2)<$O18^2,1,-1)*$O18/2^20 -> 3.1043212 | AR18: =AQ18+IF(AQ18*SQRT($N18^2+($M18+AQ18)^2)<$O18^2,1,-1)*$O18/2^21 -> 3.1043259 | AS18: =AR18+IF(AR18*SQRT($N18^2+($M18+AR18)^2)<$O18^2,1,-1)*$O18/2^22 -> 3.1043236 | AT18: =AS18+IF(AS18*SQRT($N18^2+($M18+AS18)^2)<$O18^2,1,-1)*$O18/2^23 -> 3.1043224 | AU18: =AT18+IF(AT18*SQRT($N18^2+($M18+AT18)^2)<$O18^2,1,-1)*$O18/2^24 -> 3.1043218
B19: Speed sweep 8 | C19: =IF(AND(Inputs!E33="OK",Inputs!E34="OK"),Inputs!C33*Inputs!C34*7/20,NA()) -> 126 | D19: =0 -> 0 | E19: =1 -> 1 | F19: 1 | G19: =C19/3.6 -> 35 | H19: =IF(Inputs!E27="OK",0.5*Inputs!C27*Inputs!C58*G19^2,NA()) -> 4.802 | I19: =IF(F19=0,0,H19+Inputs!C55*D19) -> 4.802 | J19: =IF(F19=0,0,IF(AND(ISNUMBER(E19),E19>=1,E19<=10),Inputs!C56*E19,NA())) -> 11.437006 | K19: =SQRT(I19^2+J19^2) -> 12.404205 | L19: =IF(F19=0,0,DEGREES(ATAN(I19/J19))) -> 22.775837 | M19: =IF(F19=0,0,G19*I19/K19) -> 13.549438 | N19: =IF(F19=0,0,G19*J19/K19) -> 32.270927 | O19: =IF(F19=0,0,IF(Inputs!E27="OK",SQRT(K19/(2*Inputs!C27*Inputs!C57)),NA())) -> 9.9959199 | P19: =AU19 -> 2.763261 | Q19: =K19*P19 -> 34.276056 | R19: =I19*G19 -> 168.07 | S19: =IF(F19=0,0,IF(Inputs!E30="OK",SUM(Q19:R19)/Inputs!C30,NA())) -> 311.30162 | T19: =IF(AND(Inputs!E31="OK",Inputs!E32="OK"),S19/Inputs!C31+Inputs!C32,NA()) -> 363.89069 | U19: =T19/Inputs!C62 -> 17.328128 | V19: =IF(Inputs!E25="OK",(T19-Inputs!C32)/Inputs!C25,NA()) -> 86.472673 | W19: =IF(F19=0,0,(P19*SQRT(N19^2+(M19+P19)^2)-O19^2)/O19^2) -> 6.4420053e-08 | X19: =$O19/2 -> 4.9979599 | Y19: =X19+IF(X19*SQRT($N19^2+($M19+X19)^2)<$O19^2,1,-1)*$O19/2^2 -> 2.49898 | Z19: =Y19+IF(Y19*SQRT($N19^2+($M19+Y19)^2)<$O19^2,1,-1)*$O19/2^3 -> 3.74847 | AA19: =Z19+IF(Z19*SQRT($N19^2+($M19+Z19)^2)<$O19^2,1,-1)*$O19/2^4 -> 3.123725 | AB19: =AA19+IF(AA19*SQRT($N19^2+($M19+AA19)^2)<$O19^2,1,-1)*$O19/2^5 -> 2.8113525 | AC19: =AB19+IF(AB19*SQRT($N19^2+($M19+AB19)^2)<$O19^2,1,-1)*$O19/2^6 -> 2.6551662 | AD19: =AC19+IF(AC19*SQRT($N19^2+($M19+AC19)^2)<$O19^2,1,-1)*$O19/2^7 -> 2.7332593 | AE19: =AD19+IF(AD19*SQRT($N19^2+($M19+AD19)^2)<$O19^2,1,-1)*$O19/2^8 -> 2.7723059 | AF19: =AE19+IF(AE19*SQRT($N19^2+($M19+AE19)^2)<$O19^2,1,-1)*$O19/2^9 -> 2.7527826 | AG19: =AF19+IF(AF19*SQRT($N19^2+($M19+AF19)^2)<$O19^2,1,-1)*$O19/2^10 -> 2.7625443 | AH19: =AG19+IF(AG19*SQRT($N19^2+($M19+AG19)^2)<$O19^2,1,-1)*$O19/2^11 -> 2.7674251 | AI19: =AH19+IF(AH19*SQRT($N19^2+($M19+AH19)^2)<$O19^2,1,-1)*$O19/2^12 -> 2.7649847 | AJ19: =AI19+IF(AI19*SQRT($N19^2+($M19+AI19)^2)<$O19^2,1,-1)*$O19/2^13 -> 2.7637645 | AK19: =AJ19+IF(AJ19*SQRT($N19^2+($M19+AJ19)^2)<$O19^2,1,-1)*$O19/2^14 -> 2.7631544 | AL19: =AK19+IF(AK19*SQRT($N19^2+($M19+AK19)^2)<$O19^2,1,-1)*$O19/2^15 -> 2.7634594 | AM19: =AL19+IF(AL19*SQRT($N19^2+($M19+AL19)^2)<$O19^2,1,-1)*$O19/2^16 -> 2.7633069 | AN19: =AM19+IF(AM19*SQRT($N19^2+($M19+AM19)^2)<$O19^2,1,-1)*$O19/2^17 -> 2.7632306 | AO19: =AN19+IF(AN19*SQRT($N19^2+($M19+AN19)^2)<$O19^2,1,-1)*$O19/2^18 -> 2.7632688 | AP19: =AO19+IF(AO19*SQRT($N19^2+($M19+AO19)^2)<$O19^2,1,-1)*$O19/2^19 -> 2.7632497 | AQ19: =AP19+IF(AP19*SQRT($N19^2+($M19+AP19)^2)<$O19^2,1,-1)*$O19/2^20 -> 2.7632592 | AR19: =AQ19+IF(AQ19*SQRT($N19^2+($M19+AQ19)^2)<$O19^2,1,-1)*$O19/2^21 -> 2.763264 | AS19: =AR19+IF(AR19*SQRT($N19^2+($M19+AR19)^2)<$O19^2,1,-1)*$O19/2^22 -> 2.7632616 | AT19: =AS19+IF(AS19*SQRT($N19^2+($M19+AS19)^2)<$O19^2,1,-1)*$O19/2^23 -> 2.7632604 | AU19: =AT19+IF(AT19*SQRT($N19^2+($M19+AT19)^2)<$O19^2,1,-1)*$O19/2^24 -> 2.763261
B20: Speed sweep 9 | C20: =IF(AND(Inputs!E33="OK",Inputs!E34="OK"),Inputs!C33*Inputs!C34*8/20,NA()) -> 144 | D20: =0 -> 0 | E20: =1 -> 1 | F20: 1 | G20: =C20/3.6 -> 40 | H20: =IF(Inputs!E27="OK",0.5*Inputs!C27*Inputs!C58*G20^2,NA()) -> 6.272 | I20: =IF(F20=0,0,H20+Inputs!C55*D20) -> 6.272 | J20: =IF(F20=0,0,IF(AND(ISNUMBER(E20),E20>=1,E20<=10),Inputs!C56*E20,NA())) -> 11.437006 | K20: =SQRT(I20^2+J20^2) -> 13.043891 | L20: =IF(F20=0,0,DEGREES(ATAN(I20/J20))) -> 28.740156 | M20: =IF(F20=0,0,G20*I20/K20) -> 19.233525 | N20: =IF(F20=0,0,G20*J20/K20) -> 35.072375 | O20: =IF(F20=0,0,IF(Inputs!E27="OK",SQRT(K20/(2*Inputs!C27*Inputs!C57)),NA())) -> 10.250425 | P20: =AU20 -> 2.5450756 | Q20: =K20*P20 -> 33.197688 | R20: =I20*G20 -> 250.88 | S20: =IF(F20=0,0,IF(Inputs!E30="OK",SUM(Q20:R20)/Inputs!C30,NA())) -> 437.0426 | T20: =IF(AND(Inputs!E31="OK",Inputs!E32="OK"),S20/Inputs!C31+Inputs!C32,NA()) -> 503.60288 | U20: =T20/Inputs!C62 -> 23.98109 | V20: =IF(Inputs!E25="OK",(T20-Inputs!C32)/Inputs!C25,NA()) -> 121.40072 | W20: =IF(F20=0,0,(P20*SQRT(N20^2+(M20+P20)^2)-O20^2)/O20^2) -> 5.7151359e-08 | X20: =$O20/2 -> 5.1252125 | Y20: =X20+IF(X20*SQRT($N20^2+($M20+X20)^2)<$O20^2,1,-1)*$O20/2^2 -> 2.5626063 | Z20: =Y20+IF(Y20*SQRT($N20^2+($M20+Y20)^2)<$O20^2,1,-1)*$O20/2^3 -> 1.2813031 | AA20: =Z20+IF(Z20*SQRT($N20^2+($M20+Z20)^2)<$O20^2,1,-1)*$O20/2^4 -> 1.9219547 | AB20: =AA20+IF(AA20*SQRT($N20^2+($M20+AA20)^2)<$O20^2,1,-1)*$O20/2^5 -> 2.2422805 | AC20: =AB20+IF(AB20*SQRT($N20^2+($M20+AB20)^2)<$O20^2,1,-1)*$O20/2^6 -> 2.4024434 | AD20: =AC20+IF(AC20*SQRT($N20^2+($M20+AC20)^2)<$O20^2,1,-1)*$O20/2^7 -> 2.4825248 | AE20: =AD20+IF(AD20*SQRT($N20^2+($M20+AD20)^2)<$O20^2,1,-1)*$O20/2^8 -> 2.5225655 | AF20: =AE20+IF(AE20*SQRT($N20^2+($M20+AE20)^2)<$O20^2,1,-1)*$O20/2^9 -> 2.5425859 | AG20: =AF20+IF(AF20*SQRT($N20^2+($M20+AF20)^2)<$O20^2,1,-1)*$O20/2^10 -> 2.5525961 | AH20: =AG20+IF(AG20*SQRT($N20^2+($M20+AG20)^2)<$O20^2,1,-1)*$O20/2^11 -> 2.547591 | AI20: =AH20+IF(AH20*SQRT($N20^2+($M20+AH20)^2)<$O20^2,1,-1)*$O20/2^12 -> 2.5450884 | AJ20: =AI20+IF(AI20*SQRT($N20^2+($M20+AI20)^2)<$O20^2,1,-1)*$O20/2^13 -> 2.5438372 | AK20: =AJ20+IF(AJ20*SQRT($N20^2+($M20+AJ20)^2)<$O20^2,1,-1)*$O20/2^14 -> 2.5444628 | AL20: =AK20+IF(AK20*SQRT($N20^2+($M20+AK20)^2)<$O20^2,1,-1)*$O20/2^15 -> 2.5447756 | AM20: =AL20+IF(AL20*SQRT($N20^2+($M20+AL20)^2)<$O20^2,1,-1)*$O20/2^16 -> 2.544932 | AN20: =AM20+IF(AM20*SQRT($N20^2+($M20+AM20)^2)<$O20^2,1,-1)*$O20/2^17 -> 2.5450102 | AO20: =AN20+IF(AN20*SQRT($N20^2+($M20+AN20)^2)<$O20^2,1,-1)*$O20/2^18 -> 2.5450493 | AP20: =AO20+IF(AO20*SQRT($N20^2+($M20+AO20)^2)<$O20^2,1,-1)*$O20/2^19 -> 2.5450689 | AQ20: =AP20+IF(AP20*SQRT($N20^2+($M20+AP20)^2)<$O20^2,1,-1)*$O20/2^20 -> 2.5450787 | AR20: =AQ20+IF(AQ20*SQRT($N20^2+($M20+AQ20)^2)<$O20^2,1,-1)*$O20/2^21 -> 2.5450738 | AS20: =AR20+IF(AR20*SQRT($N20^2+($M20+AR20)^2)<$O20^2,1,-1)*$O20/2^22 -> 2.5450762 | AT20: =AS20+IF(AS20*SQRT($N20^2+($M20+AS20)^2)<$O20^2,1,-1)*$O20/2^23 -> 2.545075 | AU20: =AT20+IF(AT20*SQRT($N20^2+($M20+AT20)^2)<$O20^2,1,-1)*$O20/2^24 -> 2.5450756
B21: Speed sweep 10 | C21: =IF(AND(Inputs!E33="OK",Inputs!E34="OK"),Inputs!C33*Inputs!C34*9/20,NA()) -> 162 | D21: =0 -> 0 | E21: =1 -> 1 | F21: 1 | G21: =C21/3.6 -> 45 | H21: =IF(Inputs!E27="OK",0.5*Inputs!C27*Inputs!C58*G21^2,NA()) -> 7.938 | I21: =IF(F21=0,0,H21+Inputs!C55*D21) -> 7.938 | J21: =IF(F21=0,0,IF(AND(ISNUMBER(E21),E21>=1,E21<=10),Inputs!C56*E21,NA())) -> 11.437006 | K21: =SQRT(I21^2+J21^2) -> 13.921815 | L21: =IF(F21=0,0,DEGREES(ATAN(I21/J21))) -> 34.763076 | M21: =IF(F21=0,0,G21*I21/K21) -> 25.658292 | N21: =IF(F21=0,0,G21*J21/K21) -> 36.968257 | O21: =IF(F21=0,0,IF(Inputs!E27="OK",SQRT(K21/(2*Inputs!C27*Inputs!C57)),NA())) -> 10.589763 | P21: =AU21 -> 2.4158393 | Q21: =K21*P21 -> 33.632868 | R21: =I21*G21 -> 357.21 | S21: =IF(F21=0,0,IF(Inputs!E30="OK",SUM(Q21:R21)/Inputs!C30,NA())) -> 601.29672 | T21: =IF(AND(Inputs!E31="OK",Inputs!E32="OK"),S21/Inputs!C31+Inputs!C32,NA()) -> 686.10747 | U21: =T21/Inputs!C62 -> 32.671784 | V21: =IF(Inputs!E25="OK",(T21-Inputs!C32)/Inputs!C25,NA()) -> 167.02687 | W21: =IF(F21=0,0,(P21*SQRT(N21^2+(M21+P21)^2)-O21^2)/O21^2) -> -1.2226612e-07 | X21: =$O21/2 -> 5.2948814 | Y21: =X21+IF(X21*SQRT($N21^2+($M21+X21)^2)<$O21^2,1,-1)*$O21/2^2 -> 2.6474407 | Z21: =Y21+IF(Y21*SQRT($N21^2+($M21+Y21)^2)<$O21^2,1,-1)*$O21/2^3 -> 1.3237204 | AA21: =Z21+IF(Z21*SQRT($N21^2+($M21+Z21)^2)<$O21^2,1,-1)*$O21/2^4 -> 1.9855805 | AB21: =AA21+IF(AA21*SQRT($N21^2+($M21+AA21)^2)<$O21^2,1,-1)*$O21/2^5 -> 2.3165106 | AC21: =AB21+IF(AB21*SQRT($N21^2+($M21+AB21)^2)<$O21^2,1,-1)*$O21/2^6 -> 2.4819757 | AD21: =AC21+IF(AC21*SQRT($N21^2+($M21+AC21)^2)<$O21^2,1,-1)*$O21/2^7 -> 2.3992431 | AE21: =AD21+IF(AD21*SQRT($N21^2+($M21+AD21)^2)<$O21^2,1,-1)*$O21/2^8 -> 2.4406094 | AF21: =AE21+IF(AE21*SQRT($N21^2+($M21+AE21)^2)<$O21^2,1,-1)*$O21/2^9 -> 2.4199263 | AG21: =AF21+IF(AF21*SQRT($N21^2+($M21+AF21)^2)<$O21^2,1,-1)*$O21/2^10 -> 2.4095847 | AH21: =AG21+IF(AG21*SQRT($N21^2+($M21+AG21)^2)<$O21^2,1,-1)*$O21/2^11 -> 2.4147555 | AI21: =AH21+IF(AH21*SQRT($N21^2+($M21+AH21)^2)<$O21^2,1,-1)*$O21/2^12 -> 2.4173409 | AJ21: =AI21+IF(AI21*SQRT($N21^2+($M21+AI21)^2)<$O21^2,1,-1)*$O21/2^13 -> 2.4160482 | AK21: =AJ21+IF(AJ21*SQRT($N21^2+($M21+AJ21)^2)<$O21^2,1,-1)*$O21/2^14 -> 2.4154018 | AL21: =AK21+IF(AK21*SQRT($N21^2+($M21+AK21)^2)<$O21^2,1,-1)*$O21/2^15 -> 2.415725 | AM21: =AL21+IF(AL21*SQRT($N21^2+($M21+AL21)^2)<$O21^2,1,-1)*$O21/2^16 -> 2.4158866 | AN21: =AM21+IF(AM21*SQRT($N21^2+($M21+AM21)^2)<$O21^2,1,-1)*$O21/2^17 -> 2.4158058 | AO21: =AN21+IF(AN21*SQRT($N21^2+($M21+AN21)^2)<$O21^2,1,-1)*$O21/2^18 -> 2.4158462 | AP21: =AO21+IF(AO21*SQRT($N21^2+($M21+AO21)^2)<$O21^2,1,-1)*$O21/2^19 -> 2.415826 | AQ21: =AP21+IF(AP21*SQRT($N21^2+($M21+AP21)^2)<$O21^2,1,-1)*$O21/2^20 -> 2.4158361 | AR21: =AQ21+IF(AQ21*SQRT($N21^2+($M21+AQ21)^2)<$O21^2,1,-1)*$O21/2^21 -> 2.4158412 | AS21: =AR21+IF(AR21*SQRT($N21^2+($M21+AR21)^2)<$O21^2,1,-1)*$O21/2^22 -> 2.4158386 | AT21: =AS21+IF(AS21*SQRT($N21^2+($M21+AS21)^2)<$O21^2,1,-1)*$O21/2^23 -> 2.4158399 | AU21: =AT21+IF(AT21*SQRT($N21^2+($M21+AT21)^2)<$O21^2,1,-1)*$O21/2^24 -> 2.4158393
B22: Speed sweep 11 | C22: =IF(AND(Inputs!E33="OK",Inputs!E34="OK"),Inputs!C33*Inputs!C34*10/20,NA()) -> 180 | D22: =0 -> 0 | E22: =1 -> 1 | F22: 1 | G22: =C22/3.6 -> 50 | H22: =IF(Inputs!E27="OK",0.5*Inputs!C27*Inputs!C58*G22^2,NA()) -> 9.8 | I22: =IF(F22=0,0,H22+Inputs!C55*D22) -> 9.8 | J22: =IF(F22=0,0,IF(AND(ISNUMBER(E22),E22>=1,E22<=10),Inputs!C56*E22,NA())) -> 11.437006 | K22: =SQRT(I22^2+J22^2) -> 15.061378 | L22: =IF(F22=0,0,DEGREES(ATAN(I22/J22))) -> 40.592203 | M22: =IF(F22=0,0,G22*I22/K22) -> 32.533545 | N22: =IF(F22=0,0,G22*J22/K22) -> 37.967993 | O22: =IF(F22=0,0,IF(Inputs!E27="OK",SQRT(K22/(2*Inputs!C27*Inputs!C57)),NA())) -> 11.014649 | P22: =AU22 -> 2.3529454 | Q22: =K22*P22 -> 35.438599 | R22: =I22*G22 -> 490 | S22: =IF(F22=0,0,IF(Inputs!E30="OK",SUM(Q22:R22)/Inputs!C30,NA())) -> 808.36708 | T22: =IF(AND(Inputs!E31="OK",Inputs!E32="OK"),S22/Inputs!C31+Inputs!C32,NA()) -> 916.18564 | U22: =T22/Inputs!C62 -> 43.627888 | V22: =IF(Inputs!E25="OK",(T22-Inputs!C32)/Inputs!C25,NA()) -> 224.54641 | W22: =IF(F22=0,0,(P22*SQRT(N22^2+(M22+P22)^2)-O22^2)/O22^2) -> -8.9054296e-08 | X22: =$O22/2 -> 5.5073243 | Y22: =X22+IF(X22*SQRT($N22^2+($M22+X22)^2)<$O22^2,1,-1)*$O22/2^2 -> 2.7536622 | Z22: =Y22+IF(Y22*SQRT($N22^2+($M22+Y22)^2)<$O22^2,1,-1)*$O22/2^3 -> 1.3768311 | AA22: =Z22+IF(Z22*SQRT($N22^2+($M22+Z22)^2)<$O22^2,1,-1)*$O22/2^4 -> 2.0652466 | AB22: =AA22+IF(AA22*SQRT($N22^2+($M22+AA22)^2)<$O22^2,1,-1)*$O22/2^5 -> 2.4094544 | AC22: =AB22+IF(AB22*SQRT($N22^2+($M22+AB22)^2)<$O22^2,1,-1)*$O22/2^6 -> 2.2373505 | AD22: =AC22+IF(AC22*SQRT($N22^2+($M22+AC22)^2)<$O22^2,1,-1)*$O22/2^7 -> 2.3234025 | AE22: =AD22+IF(AD22*SQRT($N22^2+($M22+AD22)^2)<$O22^2,1,-1)*$O22/2^8 -> 2.3664284 | AF22: =AE22+IF(AE22*SQRT($N22^2+($M22+AE22)^2)<$O22^2,1,-1)*$O22/2^9 -> 2.3449154 | AG22: =AF22+IF(AF22*SQRT($N22^2+($M22+AF22)^2)<$O22^2,1,-1)*$O22/2^10 -> 2.3556719 | AH22: =AG22+IF(AG22*SQRT($N22^2+($M22+AG22)^2)<$O22^2,1,-1)*$O22/2^11 -> 2.3502937 | AI22: =AH22+IF(AH22*SQRT($N22^2+($M22+AH22)^2)<$O22^2,1,-1)*$O22/2^12 -> 2.3529828 | AJ22: =AI22+IF(AI22*SQRT($N22^2+($M22+AI22)^2)<$O22^2,1,-1)*$O22/2^13 -> 2.3516382 | AK22: =AJ22+IF(AJ22*SQRT($N22^2+($M22+AJ22)^2)<$O22^2,1,-1)*$O22/2^14 -> 2.3523105 | AL22: =AK22+IF(AK22*SQRT($N22^2+($M22+AK22)^2)<$O22^2,1,-1)*$O22/2^15 -> 2.3526467 | AM22: =AL22+IF(AL22*SQRT($N22^2+($M22+AL22)^2)<$O22^2,1,-1)*$O22/2^16 -> 2.3528147 | AN22: =AM22+IF(AM22*SQRT($N22^2+($M22+AM22)^2)<$O22^2,1,-1)*$O22/2^17 -> 2.3528988 | AO22: =AN22+IF(AN22*SQRT($N22^2+($M22+AN22)^2)<$O22^2,1,-1)*$O22/2^18 -> 2.3529408 | AP22: =AO22+IF(AO22*SQRT($N22^2+($M22+AO22)^2)<$O22^2,1,-1)*$O22/2^19 -> 2.3529618 | AQ22: =AP22+IF(AP22*SQRT($N22^2+($M22+AP22)^2)<$O22^2,1,-1)*$O22/2^20 -> 2.3529513 | AR22: =AQ22+IF(AQ22*SQRT($N22^2+($M22+AQ22)^2)<$O22^2,1,-1)*$O22/2^21 -> 2.352946 | AS22: =AR22+IF(AR22*SQRT($N22^2+($M22+AR22)^2)<$O22^2,1,-1)*$O22/2^22 -> 2.3529434 | AT22: =AS22+IF(AS22*SQRT($N22^2+($M22+AS22)^2)<$O22^2,1,-1)*$O22/2^23 -> 2.3529447 | AU22: =AT22+IF(AT22*SQRT($N22^2+($M22+AT22)^2)<$O22^2,1,-1)*$O22/2^24 -> 2.3529454
